2025-04-10 15:48:08,901 INFO    MainThread:181610 [wandb_init.py:setup_run_log_directory():647] Logging user logs to ./wandb/run-20250410_154808-gmkainry/logs/debug.log
2025-04-10 15:48:08,901 INFO    MainThread:181610 [wandb_init.py:setup_run_log_directory():648] Logging internal logs to ./wandb/run-20250410_154808-gmkainry/logs/debug-internal.log
2025-04-10 15:48:08,901 INFO    MainThread:181610 [wandb_init.py:init():761] calling init triggers
2025-04-10 15:48:08,901 INFO    MainThread:181610 [wandb_init.py:init():766] wandb.init called with sweep_config: {}
config: {'_wandb': {}}
2025-04-10 15:48:08,901 INFO    MainThread:181610 [wandb_init.py:init():784] starting backend
2025-04-10 15:48:08,901 INFO    MainThread:181610 [wandb_init.py:init():788] sending inform_init request
2025-04-10 15:48:08,902 INFO    MainThread:181610 [backend.py:_multiprocessing_setup():97] multiprocessing start_methods=fork,spawn,forkserver, using: spawn
2025-04-10 15:48:08,903 INFO    MainThread:181610 [wandb_init.py:init():803] backend started and connected
2025-04-10 15:48:08,907 INFO    MainThread:181610 [wandb_run.py:_label_probe_notebook():1204] probe notebook
2025-04-10 15:48:08,907 INFO    MainThread:181610 [wandb_init.py:init():896] updated telemetry
2025-04-10 15:48:08,912 INFO    MainThread:181610 [wandb_init.py:init():920] communicating run to backend with 90.0 second timeout
2025-04-10 15:49:38,919 ERROR   MainThread:181610 [wandb_init.py:init():1481] error in wandb.init()
Traceback (most recent call last):
  File "/home/user/anaconda3/lib/python3.12/asyncio/tasks.py", line 520, in wait_for
    return await fut
           ^^^^^^^^^
  File "/home/user/anaconda3/lib/python3.12/asyncio/locks.py", line 212, in wait
    await fut
asyncio.exceptions.CancelledError

The above exception was the direct cause of the following exception:

Traceback (most recent call last):
  File "/home/user/anaconda3/lib/python3.12/site-packages/wandb/sdk/mailbox/handles.py", line 141, in wait_async
    await asyncio.wait_for(evt.wait(), timeout=timeout)
  File "/home/user/anaconda3/lib/python3.12/asyncio/tasks.py", line 519, in wait_for
    async with timeouts.timeout(timeout):
  File "/home/user/anaconda3/lib/python3.12/asyncio/timeouts.py", line 115, in __aexit__
    raise TimeoutError from exc_val
TimeoutError

The above exception was the direct cause of the following exception:

Traceback (most recent call last):
  File "/home/user/anaconda3/lib/python3.12/site-packages/wandb/sdk/wandb_init.py", line 946, in init
    result = wait_with_progress(
             ^^^^^^^^^^^^^^^^^^^
  File "/home/user/anaconda3/lib/python3.12/site-packages/wandb/sdk/mailbox/wait_with_progress.py", line 23, in wait_with_progress
    return wait_all_with_progress(
           ^^^^^^^^^^^^^^^^^^^^^^^
  File "/home/user/anaconda3/lib/python3.12/site-packages/wandb/sdk/mailbox/wait_with_progress.py", line 86, in wait_all_with_progress
    return asyncio_compat.run(progress_loop_with_timeout)
           ^^^^^^^^^^^^^^^^^^^^^^^^^^^^^^^^^^^^^^^^^^^^^^
  File "/home/user/anaconda3/lib/python3.12/site-packages/wandb/sdk/lib/asyncio_compat.py", line 30, in run
    return future.result()
           ^^^^^^^^^^^^^^^
  File "/home/user/anaconda3/lib/python3.12/concurrent/futures/_base.py", line 456, in result
    return self.__get_result()
           ^^^^^^^^^^^^^^^^^^^
  File "/home/user/anaconda3/lib/python3.12/concurrent/futures/_base.py", line 401, in __get_result
    raise self._exception
  File "/home/user/anaconda3/lib/python3.12/concurrent/futures/thread.py", line 58, in run
    result = self.fn(*self.args, **self.kwargs)
             ^^^^^^^^^^^^^^^^^^^^^^^^^^^^^^^^^^
  File "/home/user/anaconda3/lib/python3.12/site-packages/wandb/sdk/lib/asyncio_compat.py", line 74, in run
    return asyncio.run(self._run_or_cancel(fn))
           ^^^^^^^^^^^^^^^^^^^^^^^^^^^^^^^^^^^^
  File "/home/user/anaconda3/lib/python3.12/asyncio/runners.py", line 194, in run
    return runner.run(main)
           ^^^^^^^^^^^^^^^^
  File "/home/user/anaconda3/lib/python3.12/asyncio/runners.py", line 118, in run
    return self._loop.run_until_complete(task)
           ^^^^^^^^^^^^^^^^^^^^^^^^^^^^^^^^^^^
  File "/home/user/anaconda3/lib/python3.12/asyncio/base_events.py", line 687, in run_until_complete
    return future.result()
           ^^^^^^^^^^^^^^^
  File "/home/user/anaconda3/lib/python3.12/site-packages/wandb/sdk/lib/asyncio_compat.py", line 98, in _run_or_cancel
    return fn_task.result()
           ^^^^^^^^^^^^^^^^
  File "/home/user/anaconda3/lib/python3.12/site-packages/wandb/sdk/mailbox/wait_with_progress.py", line 81, in progress_loop_with_timeout
    return await _wait_handles_async(
           ^^^^^^^^^^^^^^^^^^^^^^^^^^
  File "/home/user/anaconda3/lib/python3.12/site-packages/wandb/sdk/mailbox/wait_with_progress.py", line 129, in _wait_handles_async
    async with asyncio_compat.open_task_group() as task_group:
  File "/home/user/anaconda3/lib/python3.12/contextlib.py", line 217, in __aexit__
    await anext(self.gen)
  File "/home/user/anaconda3/lib/python3.12/site-packages/wandb/sdk/lib/asyncio_compat.py", line 190, in open_task_group
    await task_group._wait_all()
  File "/home/user/anaconda3/lib/python3.12/site-packages/wandb/sdk/lib/asyncio_compat.py", line 159, in _wait_all
    raise exc
  File "/home/user/anaconda3/lib/python3.12/site-packages/wandb/sdk/mailbox/wait_with_progress.py", line 127, in wait_single
    results[index] = await handle.wait_async(timeout=timeout)
                     ^^^^^^^^^^^^^^^^^^^^^^^^^^^^^^^^^^^^^^^^
  File "/home/user/anaconda3/lib/python3.12/site-packages/wandb/sdk/mailbox/handles.py", line 150, in wait_async
    raise TimeoutError(
TimeoutError: Timed out waiting for response on 2wlupntq6zvk

During handling of the above exception, another exception occurred:

Traceback (most recent call last):
  File "/home/user/anaconda3/lib/python3.12/site-packages/wandb/sdk/wandb_init.py", line 1471, in init
    return wi.init(run_settings, run_config)
           ^^^^^^^^^^^^^^^^^^^^^^^^^^^^^^^^^
  File "/home/user/anaconda3/lib/python3.12/site-packages/wandb/sdk/wandb_init.py", line 959, in init
    raise CommError(
wandb.errors.errors.CommError: Run initialization has timed out after 90.0 sec. Please try increasing the timeout with the `init_timeout` setting: `wandb.init(settings=wandb.Settings(init_timeout=120))`.
2025-04-10 15:55:13,496 INFO    MainThread:181610 [wandb_init.py:setup_run_log_directory():647] Logging user logs to ./wandb/run-20250410_155513-9wx6k7sq/logs/debug.log
2025-04-10 15:55:13,496 INFO    MainThread:181610 [wandb_init.py:setup_run_log_directory():648] Logging internal logs to ./wandb/run-20250410_155513-9wx6k7sq/logs/debug-internal.log
2025-04-10 15:55:13,496 INFO    MainThread:181610 [wandb_init.py:init():761] calling init triggers
2025-04-10 15:55:13,496 INFO    MainThread:181610 [wandb_init.py:init():766] wandb.init called with sweep_config: {}
config: {'_wandb': {}}
2025-04-10 15:55:13,496 INFO    MainThread:181610 [wandb_init.py:init():784] starting backend
2025-04-10 15:55:13,496 INFO    MainThread:181610 [wandb_init.py:init():788] sending inform_init request
2025-04-10 15:55:13,498 INFO    MainThread:181610 [backend.py:_multiprocessing_setup():97] multiprocessing start_methods=fork,spawn,forkserver, using: spawn
2025-04-10 15:55:13,498 INFO    MainThread:181610 [wandb_init.py:init():803] backend started and connected
2025-04-10 15:55:13,506 INFO    MainThread:181610 [wandb_run.py:_label_probe_notebook():1204] probe notebook
2025-04-10 15:55:13,506 INFO    MainThread:181610 [wandb_init.py:init():896] updated telemetry
2025-04-10 15:55:13,512 INFO    MainThread:181610 [wandb_init.py:init():920] communicating run to backend with 90.0 second timeout
2025-04-10 15:56:43,516 ERROR   MainThread:181610 [wandb_init.py:init():1481] error in wandb.init()
Traceback (most recent call last):
  File "/home/user/anaconda3/lib/python3.12/asyncio/tasks.py", line 520, in wait_for
    return await fut
           ^^^^^^^^^
  File "/home/user/anaconda3/lib/python3.12/asyncio/locks.py", line 212, in wait
    await fut
asyncio.exceptions.CancelledError

The above exception was the direct cause of the following exception:

Traceback (most recent call last):
  File "/home/user/anaconda3/lib/python3.12/site-packages/wandb/sdk/mailbox/handles.py", line 141, in wait_async
    await asyncio.wait_for(evt.wait(), timeout=timeout)
  File "/home/user/anaconda3/lib/python3.12/asyncio/tasks.py", line 519, in wait_for
    async with timeouts.timeout(timeout):
  File "/home/user/anaconda3/lib/python3.12/asyncio/timeouts.py", line 115, in __aexit__
    raise TimeoutError from exc_val
TimeoutError

The above exception was the direct cause of the following exception:

Traceback (most recent call last):
  File "/home/user/anaconda3/lib/python3.12/site-packages/wandb/sdk/wandb_init.py", line 946, in init
    result = wait_with_progress(
             ^^^^^^^^^^^^^^^^^^^
  File "/home/user/anaconda3/lib/python3.12/site-packages/wandb/sdk/mailbox/wait_with_progress.py", line 23, in wait_with_progress
    return wait_all_with_progress(
           ^^^^^^^^^^^^^^^^^^^^^^^
  File "/home/user/anaconda3/lib/python3.12/site-packages/wandb/sdk/mailbox/wait_with_progress.py", line 86, in wait_all_with_progress
    return asyncio_compat.run(progress_loop_with_timeout)
           ^^^^^^^^^^^^^^^^^^^^^^^^^^^^^^^^^^^^^^^^^^^^^^
  File "/home/user/anaconda3/lib/python3.12/site-packages/wandb/sdk/lib/asyncio_compat.py", line 30, in run
    return future.result()
           ^^^^^^^^^^^^^^^
  File "/home/user/anaconda3/lib/python3.12/concurrent/futures/_base.py", line 456, in result
    return self.__get_result()
           ^^^^^^^^^^^^^^^^^^^
  File "/home/user/anaconda3/lib/python3.12/concurrent/futures/_base.py", line 401, in __get_result
    raise self._exception
  File "/home/user/anaconda3/lib/python3.12/concurrent/futures/thread.py", line 58, in run
    result = self.fn(*self.args, **self.kwargs)
             ^^^^^^^^^^^^^^^^^^^^^^^^^^^^^^^^^^
  File "/home/user/anaconda3/lib/python3.12/site-packages/wandb/sdk/lib/asyncio_compat.py", line 74, in run
    return asyncio.run(self._run_or_cancel(fn))
           ^^^^^^^^^^^^^^^^^^^^^^^^^^^^^^^^^^^^
  File "/home/user/anaconda3/lib/python3.12/asyncio/runners.py", line 194, in run
    return runner.run(main)
           ^^^^^^^^^^^^^^^^
  File "/home/user/anaconda3/lib/python3.12/asyncio/runners.py", line 118, in run
    return self._loop.run_until_complete(task)
           ^^^^^^^^^^^^^^^^^^^^^^^^^^^^^^^^^^^
  File "/home/user/anaconda3/lib/python3.12/asyncio/base_events.py", line 687, in run_until_complete
    return future.result()
           ^^^^^^^^^^^^^^^
  File "/home/user/anaconda3/lib/python3.12/site-packages/wandb/sdk/lib/asyncio_compat.py", line 98, in _run_or_cancel
    return fn_task.result()
           ^^^^^^^^^^^^^^^^
  File "/home/user/anaconda3/lib/python3.12/site-packages/wandb/sdk/mailbox/wait_with_progress.py", line 81, in progress_loop_with_timeout
    return await _wait_handles_async(
           ^^^^^^^^^^^^^^^^^^^^^^^^^^
  File "/home/user/anaconda3/lib/python3.12/site-packages/wandb/sdk/mailbox/wait_with_progress.py", line 129, in _wait_handles_async
    async with asyncio_compat.open_task_group() as task_group:
  File "/home/user/anaconda3/lib/python3.12/contextlib.py", line 217, in __aexit__
    await anext(self.gen)
  File "/home/user/anaconda3/lib/python3.12/site-packages/wandb/sdk/lib/asyncio_compat.py", line 190, in open_task_group
    await task_group._wait_all()
  File "/home/user/anaconda3/lib/python3.12/site-packages/wandb/sdk/lib/asyncio_compat.py", line 159, in _wait_all
    raise exc
  File "/home/user/anaconda3/lib/python3.12/site-packages/wandb/sdk/mailbox/wait_with_progress.py", line 127, in wait_single
    results[index] = await handle.wait_async(timeout=timeout)
                     ^^^^^^^^^^^^^^^^^^^^^^^^^^^^^^^^^^^^^^^^
  File "/home/user/anaconda3/lib/python3.12/site-packages/wandb/sdk/mailbox/handles.py", line 150, in wait_async
    raise TimeoutError(
TimeoutError: Timed out waiting for response on yt9vuhkiucqd

During handling of the above exception, another exception occurred:

Traceback (most recent call last):
  File "/home/user/anaconda3/lib/python3.12/site-packages/wandb/sdk/wandb_init.py", line 1471, in init
    return wi.init(run_settings, run_config)
           ^^^^^^^^^^^^^^^^^^^^^^^^^^^^^^^^^
  File "/home/user/anaconda3/lib/python3.12/site-packages/wandb/sdk/wandb_init.py", line 959, in init
    raise CommError(
wandb.errors.errors.CommError: Run initialization has timed out after 90.0 sec. Please try increasing the timeout with the `init_timeout` setting: `wandb.init(settings=wandb.Settings(init_timeout=120))`.
2025-04-10 15:58:31,098 INFO    MainThread:181610 [wandb_init.py:setup_run_log_directory():647] Logging user logs to ./wandb/run-20250410_155831-fuijrld3/logs/debug.log
2025-04-10 15:58:31,098 INFO    MainThread:181610 [wandb_init.py:setup_run_log_directory():648] Logging internal logs to ./wandb/run-20250410_155831-fuijrld3/logs/debug-internal.log
2025-04-10 15:58:31,098 INFO    MainThread:181610 [wandb_init.py:init():761] calling init triggers
2025-04-10 15:58:31,098 INFO    MainThread:181610 [wandb_init.py:init():766] wandb.init called with sweep_config: {}
config: {'_wandb': {}}
2025-04-10 15:58:31,099 INFO    MainThread:181610 [wandb_init.py:init():784] starting backend
2025-04-10 15:58:31,099 INFO    MainThread:181610 [wandb_init.py:init():788] sending inform_init request
2025-04-10 15:58:31,100 INFO    MainThread:181610 [backend.py:_multiprocessing_setup():97] multiprocessing start_methods=fork,spawn,forkserver, using: spawn
2025-04-10 15:58:31,101 INFO    MainThread:181610 [wandb_init.py:init():803] backend started and connected
2025-04-10 15:58:31,108 INFO    MainThread:181610 [wandb_run.py:_label_probe_notebook():1204] probe notebook
2025-04-10 15:58:31,109 INFO    MainThread:181610 [wandb_init.py:init():896] updated telemetry
2025-04-10 15:58:31,113 INFO    MainThread:181610 [wandb_init.py:init():920] communicating run to backend with 90.0 second timeout
2025-04-10 15:58:49,829 WARNING MainThread:181610 [wandb_init.py:init():1475] interrupted
Traceback (most recent call last):
  File "/home/user/anaconda3/lib/python3.12/site-packages/wandb/sdk/wandb_init.py", line 1471, in init
    return wi.init(run_settings, run_config)
           ^^^^^^^^^^^^^^^^^^^^^^^^^^^^^^^^^
  File "/home/user/anaconda3/lib/python3.12/site-packages/wandb/sdk/wandb_init.py", line 946, in init
    result = wait_with_progress(
             ^^^^^^^^^^^^^^^^^^^
  File "/home/user/anaconda3/lib/python3.12/site-packages/wandb/sdk/mailbox/wait_with_progress.py", line 23, in wait_with_progress
    return wait_all_with_progress(
           ^^^^^^^^^^^^^^^^^^^^^^^
  File "/home/user/anaconda3/lib/python3.12/site-packages/wandb/sdk/mailbox/wait_with_progress.py", line 86, in wait_all_with_progress
    return asyncio_compat.run(progress_loop_with_timeout)
           ^^^^^^^^^^^^^^^^^^^^^^^^^^^^^^^^^^^^^^^^^^^^^^
  File "/home/user/anaconda3/lib/python3.12/site-packages/wandb/sdk/lib/asyncio_compat.py", line 30, in run
    return future.result()
           ^^^^^^^^^^^^^^^
  File "/home/user/anaconda3/lib/python3.12/concurrent/futures/_base.py", line 451, in result
    self._condition.wait(timeout)
  File "/home/user/anaconda3/lib/python3.12/threading.py", line 355, in wait
    waiter.acquire()
KeyboardInterrupt
2025-04-10 15:59:06,501 INFO    MainThread:181610 [wandb_init.py:setup_run_log_directory():647] Logging user logs to /home/user/Documents/Books/DA24S019_Assignment_2/Part_A/wandb/run-20250410_155906-5n3lhyqj/logs/debug.log
2025-04-10 15:59:06,501 INFO    MainThread:181610 [wandb_init.py:setup_run_log_directory():648] Logging internal logs to /home/user/Documents/Books/DA24S019_Assignment_2/Part_A/wandb/run-20250410_155906-5n3lhyqj/logs/debug-internal.log
2025-04-10 15:59:06,501 INFO    MainThread:181610 [wandb_init.py:init():761] calling init triggers
2025-04-10 15:59:06,501 INFO    MainThread:181610 [wandb_init.py:init():766] wandb.init called with sweep_config: {}
config: {'_wandb': {}}
2025-04-10 15:59:06,501 INFO    MainThread:181610 [wandb_init.py:init():784] starting backend
2025-04-10 15:59:06,501 INFO    MainThread:181610 [wandb_init.py:init():788] sending inform_init request
2025-04-10 15:59:06,503 INFO    MainThread:181610 [backend.py:_multiprocessing_setup():97] multiprocessing start_methods=fork,spawn,forkserver, using: spawn
2025-04-10 15:59:06,504 INFO    MainThread:181610 [wandb_init.py:init():803] backend started and connected
2025-04-10 15:59:06,510 INFO    MainThread:181610 [wandb_run.py:_label_probe_notebook():1204] probe notebook
2025-04-10 15:59:06,510 INFO    MainThread:181610 [wandb_init.py:init():896] updated telemetry
2025-04-10 15:59:06,517 INFO    MainThread:181610 [wandb_init.py:init():920] communicating run to backend with 90.0 second timeout
