2025-04-10 15:25:04 ERROR 400 response executing GraphQL.
2025-04-10 15:25:04 ERROR {"errors":[{"message":"entityName required for models query","path":["models"]}],"data":{"models":null}}
2025-04-10 15:25:04 ERROR Traceback (most recent call last):
  File "/home/user/anaconda3/lib/python3.12/site-packages/wandb/apis/normalize.py", line 25, in wrapper
    return func(*args, **kwargs)
           ^^^^^^^^^^^^^^^^^^^^^
  File "/home/user/anaconda3/lib/python3.12/site-packages/wandb/sdk/internal/internal_api.py", line 1033, in list_projects
    self.gql(
  File "/home/user/anaconda3/lib/python3.12/site-packages/wandb/sdk/internal/internal_api.py", line 370, in gql
    ret = self._retry_gql(
          ^^^^^^^^^^^^^^^^
  File "/home/user/anaconda3/lib/python3.12/site-packages/wandb/sdk/lib/retry.py", line 134, in __call__
    result = self._call_fn(*args, **kwargs)
             ^^^^^^^^^^^^^^^^^^^^^^^^^^^^^^
  File "/home/user/anaconda3/lib/python3.12/site-packages/wandb/sdk/internal/internal_api.py", line 398, in execute
    return self.client.execute(*args, **kwargs)  # type: ignore
           ^^^^^^^^^^^^^^^^^^^^^^^^^^^^^^^^^^^^
  File "/home/user/anaconda3/lib/python3.12/site-packages/wandb/vendor/gql-0.2.0/wandb_gql/client.py", line 52, in execute
    result = self._get_result(document, *args, **kwargs)
             ^^^^^^^^^^^^^^^^^^^^^^^^^^^^^^^^^^^^^^^^^^^
  File "/home/user/anaconda3/lib/python3.12/site-packages/wandb/vendor/gql-0.2.0/wandb_gql/client.py", line 60, in _get_result
    return self.transport.execute(document, *args, **kwargs)
           ^^^^^^^^^^^^^^^^^^^^^^^^^^^^^^^^^^^^^^^^^^^^^^^^^
  File "/home/user/anaconda3/lib/python3.12/site-packages/wandb/sdk/lib/gql_request.py", line 59, in execute
    request.raise_for_status()
  File "/home/user/anaconda3/lib/python3.12/site-packages/requests/models.py", line 1024, in raise_for_status
    raise HTTPError(http_error_msg, response=self)
requests.exceptions.HTTPError: 400 Client Error: Bad Request for url: https://api.wandb.ai/graphql

During handling of the above exception, another exception occurred:

Traceback (most recent call last):
  File "/home/user/anaconda3/lib/python3.12/site-packages/wandb/cli/cli.py", line 104, in wrapper
    return func(*args, **kwargs)
           ^^^^^^^^^^^^^^^^^^^^^
  File "/home/user/anaconda3/lib/python3.12/site-packages/wandb/cli/cli.py", line 197, in projects
    projects = api.list_projects(entity=entity)
               ^^^^^^^^^^^^^^^^^^^^^^^^^^^^^^^^
  File "/home/user/anaconda3/lib/python3.12/site-packages/wandb/apis/internal.py", line 92, in list_projects
    return self.api.list_projects(entity=entity)
           ^^^^^^^^^^^^^^^^^^^^^^^^^^^^^^^^^^^^^
  File "/home/user/anaconda3/lib/python3.12/site-packages/wandb/apis/normalize.py", line 42, in wrapper
    raise CommError(message, error)
wandb.errors.errors.CommError: HTTP 400: entityName required for models query

2025-04-10 17:01:07 ERROR 400 response executing GraphQL.
2025-04-10 17:01:07 ERROR {"errors":[{"message":"name required for project query","path":["project"]}],"data":{"project":null}}
2025-04-10 17:01:07 ERROR Traceback (most recent call last):
  File "/home/user/anaconda3/lib/python3.12/site-packages/wandb/apis/normalize.py", line 25, in wrapper
    return func(*args, **kwargs)
           ^^^^^^^^^^^^^^^^^^^^^
  File "/home/user/anaconda3/lib/python3.12/site-packages/wandb/sdk/internal/internal_api.py", line 1129, in sweep
    response = self.gql(
               ^^^^^^^^^
  File "/home/user/anaconda3/lib/python3.12/site-packages/wandb/sdk/internal/internal_api.py", line 370, in gql
    ret = self._retry_gql(
          ^^^^^^^^^^^^^^^^
  File "/home/user/anaconda3/lib/python3.12/site-packages/wandb/sdk/lib/retry.py", line 134, in __call__
    result = self._call_fn(*args, **kwargs)
             ^^^^^^^^^^^^^^^^^^^^^^^^^^^^^^
  File "/home/user/anaconda3/lib/python3.12/site-packages/wandb/sdk/internal/internal_api.py", line 398, in execute
    return self.client.execute(*args, **kwargs)  # type: ignore
           ^^^^^^^^^^^^^^^^^^^^^^^^^^^^^^^^^^^^
  File "/home/user/anaconda3/lib/python3.12/site-packages/wandb/vendor/gql-0.2.0/wandb_gql/client.py", line 52, in execute
    result = self._get_result(document, *args, **kwargs)
             ^^^^^^^^^^^^^^^^^^^^^^^^^^^^^^^^^^^^^^^^^^^
  File "/home/user/anaconda3/lib/python3.12/site-packages/wandb/vendor/gql-0.2.0/wandb_gql/client.py", line 60, in _get_result
    return self.transport.execute(document, *args, **kwargs)
           ^^^^^^^^^^^^^^^^^^^^^^^^^^^^^^^^^^^^^^^^^^^^^^^^^
  File "/home/user/anaconda3/lib/python3.12/site-packages/wandb/sdk/lib/gql_request.py", line 59, in execute
    request.raise_for_status()
  File "/home/user/anaconda3/lib/python3.12/site-packages/requests/models.py", line 1024, in raise_for_status
    raise HTTPError(http_error_msg, response=self)
requests.exceptions.HTTPError: 400 Client Error: Bad Request for url: https://api.wandb.ai/graphql

During handling of the above exception, another exception occurred:

Traceback (most recent call last):
  File "/home/user/anaconda3/lib/python3.12/site-packages/wandb/cli/cli.py", line 104, in wrapper
    return func(*args, **kwargs)
           ^^^^^^^^^^^^^^^^^^^^^
  File "/home/user/anaconda3/lib/python3.12/site-packages/wandb/cli/cli.py", line 1676, in agent
    wandb_agent.agent(sweep_id, entity=entity, project=project, count=count)
  File "/home/user/anaconda3/lib/python3.12/site-packages/wandb/wandb_agent.py", line 567, in agent
    return run_agent(
           ^^^^^^^^^^
  File "/home/user/anaconda3/lib/python3.12/site-packages/wandb/wandb_agent.py", line 526, in run_agent
    agent.run()
  File "/home/user/anaconda3/lib/python3.12/site-packages/wandb/wandb_agent.py", line 193, in run
    sweep_obj = self._api.sweep(self._sweep_id, "{}")
                ^^^^^^^^^^^^^^^^^^^^^^^^^^^^^^^^^^^^^
  File "/home/user/anaconda3/lib/python3.12/site-packages/wandb/apis/internal.py", line 134, in sweep
    return self.api.sweep(*args, **kwargs)
           ^^^^^^^^^^^^^^^^^^^^^^^^^^^^^^^
  File "/home/user/anaconda3/lib/python3.12/site-packages/wandb/apis/normalize.py", line 42, in wrapper
    raise CommError(message, error)
wandb.errors.errors.CommError: HTTP 400: name required for project query

2025-04-10 17:01:40 ERROR 400 response executing GraphQL.
2025-04-10 17:01:40 ERROR {"errors":[{"message":"name required for project query","path":["project"]}],"data":{"project":null}}
2025-04-10 17:01:40 ERROR Traceback (most recent call last):
  File "/home/user/anaconda3/lib/python3.12/site-packages/wandb/apis/normalize.py", line 25, in wrapper
    return func(*args, **kwargs)
           ^^^^^^^^^^^^^^^^^^^^^
  File "/home/user/anaconda3/lib/python3.12/site-packages/wandb/sdk/internal/internal_api.py", line 1129, in sweep
    response = self.gql(
               ^^^^^^^^^
  File "/home/user/anaconda3/lib/python3.12/site-packages/wandb/sdk/internal/internal_api.py", line 370, in gql
    ret = self._retry_gql(
          ^^^^^^^^^^^^^^^^
  File "/home/user/anaconda3/lib/python3.12/site-packages/wandb/sdk/lib/retry.py", line 134, in __call__
    result = self._call_fn(*args, **kwargs)
             ^^^^^^^^^^^^^^^^^^^^^^^^^^^^^^
  File "/home/user/anaconda3/lib/python3.12/site-packages/wandb/sdk/internal/internal_api.py", line 398, in execute
    return self.client.execute(*args, **kwargs)  # type: ignore
           ^^^^^^^^^^^^^^^^^^^^^^^^^^^^^^^^^^^^
  File "/home/user/anaconda3/lib/python3.12/site-packages/wandb/vendor/gql-0.2.0/wandb_gql/client.py", line 52, in execute
    result = self._get_result(document, *args, **kwargs)
             ^^^^^^^^^^^^^^^^^^^^^^^^^^^^^^^^^^^^^^^^^^^
  File "/home/user/anaconda3/lib/python3.12/site-packages/wandb/vendor/gql-0.2.0/wandb_gql/client.py", line 60, in _get_result
    return self.transport.execute(document, *args, **kwargs)
           ^^^^^^^^^^^^^^^^^^^^^^^^^^^^^^^^^^^^^^^^^^^^^^^^^
  File "/home/user/anaconda3/lib/python3.12/site-packages/wandb/sdk/lib/gql_request.py", line 59, in execute
    request.raise_for_status()
  File "/home/user/anaconda3/lib/python3.12/site-packages/requests/models.py", line 1024, in raise_for_status
    raise HTTPError(http_error_msg, response=self)
requests.exceptions.HTTPError: 400 Client Error: Bad Request for url: https://api.wandb.ai/graphql

During handling of the above exception, another exception occurred:

Traceback (most recent call last):
  File "/home/user/anaconda3/lib/python3.12/site-packages/wandb/cli/cli.py", line 104, in wrapper
    return func(*args, **kwargs)
           ^^^^^^^^^^^^^^^^^^^^^
  File "/home/user/anaconda3/lib/python3.12/site-packages/wandb/cli/cli.py", line 1676, in agent
    wandb_agent.agent(sweep_id, entity=entity, project=project, count=count)
  File "/home/user/anaconda3/lib/python3.12/site-packages/wandb/wandb_agent.py", line 567, in agent
    return run_agent(
           ^^^^^^^^^^
  File "/home/user/anaconda3/lib/python3.12/site-packages/wandb/wandb_agent.py", line 526, in run_agent
    agent.run()
  File "/home/user/anaconda3/lib/python3.12/site-packages/wandb/wandb_agent.py", line 193, in run
    sweep_obj = self._api.sweep(self._sweep_id, "{}")
                ^^^^^^^^^^^^^^^^^^^^^^^^^^^^^^^^^^^^^
  File "/home/user/anaconda3/lib/python3.12/site-packages/wandb/apis/internal.py", line 134, in sweep
    return self.api.sweep(*args, **kwargs)
           ^^^^^^^^^^^^^^^^^^^^^^^^^^^^^^^
  File "/home/user/anaconda3/lib/python3.12/site-packages/wandb/apis/normalize.py", line 42, in wrapper
    raise CommError(message, error)
wandb.errors.errors.CommError: HTTP 400: name required for project query

2025-04-10 17:05:14 ERROR Traceback (most recent call last):
  File "/home/user/anaconda3/lib/python3.12/site-packages/wandb/apis/normalize.py", line 25, in wrapper
    return func(*args, **kwargs)
           ^^^^^^^^^^^^^^^^^^^^^
  File "/home/user/anaconda3/lib/python3.12/site-packages/wandb/sdk/internal/internal_api.py", line 1139, in sweep
    raise ValueError(f"Sweep {entity}/{project}/{sweep} not found")
ValueError: Sweep da24s019/DA6401_A2/ameo4kvc not found

During handling of the above exception, another exception occurred:

Traceback (most recent call last):
  File "/home/user/anaconda3/lib/python3.12/site-packages/wandb/cli/cli.py", line 104, in wrapper
    return func(*args, **kwargs)
           ^^^^^^^^^^^^^^^^^^^^^
  File "/home/user/anaconda3/lib/python3.12/site-packages/wandb/cli/cli.py", line 1676, in agent
    wandb_agent.agent(sweep_id, entity=entity, project=project, count=count)
  File "/home/user/anaconda3/lib/python3.12/site-packages/wandb/wandb_agent.py", line 567, in agent
    return run_agent(
           ^^^^^^^^^^
  File "/home/user/anaconda3/lib/python3.12/site-packages/wandb/wandb_agent.py", line 526, in run_agent
    agent.run()
  File "/home/user/anaconda3/lib/python3.12/site-packages/wandb/wandb_agent.py", line 193, in run
    sweep_obj = self._api.sweep(self._sweep_id, "{}")
                ^^^^^^^^^^^^^^^^^^^^^^^^^^^^^^^^^^^^^
  File "/home/user/anaconda3/lib/python3.12/site-packages/wandb/apis/internal.py", line 134, in sweep
    return self.api.sweep(*args, **kwargs)
           ^^^^^^^^^^^^^^^^^^^^^^^^^^^^^^^
  File "/home/user/anaconda3/lib/python3.12/site-packages/wandb/apis/normalize.py", line 79, in wrapper
    raise CommError(message, err).with_traceback(sys.exc_info()[2])
  File "/home/user/anaconda3/lib/python3.12/site-packages/wandb/apis/normalize.py", line 25, in wrapper
    return func(*args, **kwargs)
           ^^^^^^^^^^^^^^^^^^^^^
  File "/home/user/anaconda3/lib/python3.12/site-packages/wandb/sdk/internal/internal_api.py", line 1139, in sweep
    raise ValueError(f"Sweep {entity}/{project}/{sweep} not found")
wandb.errors.errors.CommError: Sweep da24s019/DA6401_A2/ameo4kvc not found

2025-04-10 17:06:27 ERROR Traceback (most recent call last):
  File "/home/user/anaconda3/lib/python3.12/site-packages/wandb/apis/normalize.py", line 25, in wrapper
    return func(*args, **kwargs)
           ^^^^^^^^^^^^^^^^^^^^^
  File "/home/user/anaconda3/lib/python3.12/site-packages/wandb/sdk/internal/internal_api.py", line 1139, in sweep
    raise ValueError(f"Sweep {entity}/{project}/{sweep} not found")
ValueError: Sweep da24s019-indian-institute-of-technology-madras/DA6401_A2/ameo4kvc not found

During handling of the above exception, another exception occurred:

Traceback (most recent call last):
  File "/home/user/anaconda3/lib/python3.12/site-packages/wandb/cli/cli.py", line 104, in wrapper
    return func(*args, **kwargs)
           ^^^^^^^^^^^^^^^^^^^^^
  File "/home/user/anaconda3/lib/python3.12/site-packages/wandb/cli/cli.py", line 1676, in agent
    wandb_agent.agent(sweep_id, entity=entity, project=project, count=count)
  File "/home/user/anaconda3/lib/python3.12/site-packages/wandb/wandb_agent.py", line 567, in agent
    return run_agent(
           ^^^^^^^^^^
  File "/home/user/anaconda3/lib/python3.12/site-packages/wandb/wandb_agent.py", line 526, in run_agent
    agent.run()
  File "/home/user/anaconda3/lib/python3.12/site-packages/wandb/wandb_agent.py", line 193, in run
    sweep_obj = self._api.sweep(self._sweep_id, "{}")
                ^^^^^^^^^^^^^^^^^^^^^^^^^^^^^^^^^^^^^
  File "/home/user/anaconda3/lib/python3.12/site-packages/wandb/apis/internal.py", line 134, in sweep
    return self.api.sweep(*args, **kwargs)
           ^^^^^^^^^^^^^^^^^^^^^^^^^^^^^^^
  File "/home/user/anaconda3/lib/python3.12/site-packages/wandb/apis/normalize.py", line 79, in wrapper
    raise CommError(message, err).with_traceback(sys.exc_info()[2])
  File "/home/user/anaconda3/lib/python3.12/site-packages/wandb/apis/normalize.py", line 25, in wrapper
    return func(*args, **kwargs)
           ^^^^^^^^^^^^^^^^^^^^^
  File "/home/user/anaconda3/lib/python3.12/site-packages/wandb/sdk/internal/internal_api.py", line 1139, in sweep
    raise ValueError(f"Sweep {entity}/{project}/{sweep} not found")
wandb.errors.errors.CommError: Sweep da24s019-indian-institute-of-technology-madras/DA6401_A2/ameo4kvc not found

2025-04-10 17:07:21 ERROR Traceback (most recent call last):
  File "/home/user/anaconda3/lib/python3.12/site-packages/wandb/apis/normalize.py", line 25, in wrapper
    return func(*args, **kwargs)
           ^^^^^^^^^^^^^^^^^^^^^
  File "/home/user/anaconda3/lib/python3.12/site-packages/wandb/sdk/internal/internal_api.py", line 1139, in sweep
    raise ValueError(f"Sweep {entity}/{project}/{sweep} not found")
ValueError: Sweep da24s019-indian-institute-of-technology-madras/CNN_Assignment/ameo4kvc not found

During handling of the above exception, another exception occurred:

Traceback (most recent call last):
  File "/home/user/anaconda3/lib/python3.12/site-packages/wandb/cli/cli.py", line 104, in wrapper
    return func(*args, **kwargs)
           ^^^^^^^^^^^^^^^^^^^^^
  File "/home/user/anaconda3/lib/python3.12/site-packages/wandb/cli/cli.py", line 1676, in agent
    wandb_agent.agent(sweep_id, entity=entity, project=project, count=count)
  File "/home/user/anaconda3/lib/python3.12/site-packages/wandb/wandb_agent.py", line 567, in agent
    return run_agent(
           ^^^^^^^^^^
  File "/home/user/anaconda3/lib/python3.12/site-packages/wandb/wandb_agent.py", line 526, in run_agent
    agent.run()
  File "/home/user/anaconda3/lib/python3.12/site-packages/wandb/wandb_agent.py", line 193, in run
    sweep_obj = self._api.sweep(self._sweep_id, "{}")
                ^^^^^^^^^^^^^^^^^^^^^^^^^^^^^^^^^^^^^
  File "/home/user/anaconda3/lib/python3.12/site-packages/wandb/apis/internal.py", line 134, in sweep
    return self.api.sweep(*args, **kwargs)
           ^^^^^^^^^^^^^^^^^^^^^^^^^^^^^^^
  File "/home/user/anaconda3/lib/python3.12/site-packages/wandb/apis/normalize.py", line 79, in wrapper
    raise CommError(message, err).with_traceback(sys.exc_info()[2])
  File "/home/user/anaconda3/lib/python3.12/site-packages/wandb/apis/normalize.py", line 25, in wrapper
    return func(*args, **kwargs)
           ^^^^^^^^^^^^^^^^^^^^^
  File "/home/user/anaconda3/lib/python3.12/site-packages/wandb/sdk/internal/internal_api.py", line 1139, in sweep
    raise ValueError(f"Sweep {entity}/{project}/{sweep} not found")
wandb.errors.errors.CommError: Sweep da24s019-indian-institute-of-technology-madras/CNN_Assignment/ameo4kvc not found

2025-04-10 17:08:16 ERROR Traceback (most recent call last):
  File "/home/user/anaconda3/lib/python3.12/site-packages/wandb/apis/normalize.py", line 25, in wrapper
    return func(*args, **kwargs)
           ^^^^^^^^^^^^^^^^^^^^^
  File "/home/user/anaconda3/lib/python3.12/site-packages/wandb/sdk/internal/internal_api.py", line 1139, in sweep
    raise ValueError(f"Sweep {entity}/{project}/{sweep} not found")
ValueError: Sweep da24s019-indian-institute-of-technology-madras/CNN_Assignment/0qfnbfu7 not found

During handling of the above exception, another exception occurred:

Traceback (most recent call last):
  File "/home/user/anaconda3/lib/python3.12/site-packages/wandb/cli/cli.py", line 104, in wrapper
    return func(*args, **kwargs)
           ^^^^^^^^^^^^^^^^^^^^^
  File "/home/user/anaconda3/lib/python3.12/site-packages/wandb/cli/cli.py", line 1676, in agent
    wandb_agent.agent(sweep_id, entity=entity, project=project, count=count)
  File "/home/user/anaconda3/lib/python3.12/site-packages/wandb/wandb_agent.py", line 567, in agent
    return run_agent(
           ^^^^^^^^^^
  File "/home/user/anaconda3/lib/python3.12/site-packages/wandb/wandb_agent.py", line 526, in run_agent
    agent.run()
  File "/home/user/anaconda3/lib/python3.12/site-packages/wandb/wandb_agent.py", line 193, in run
    sweep_obj = self._api.sweep(self._sweep_id, "{}")
                ^^^^^^^^^^^^^^^^^^^^^^^^^^^^^^^^^^^^^
  File "/home/user/anaconda3/lib/python3.12/site-packages/wandb/apis/internal.py", line 134, in sweep
    return self.api.sweep(*args, **kwargs)
           ^^^^^^^^^^^^^^^^^^^^^^^^^^^^^^^
  File "/home/user/anaconda3/lib/python3.12/site-packages/wandb/apis/normalize.py", line 79, in wrapper
    raise CommError(message, err).with_traceback(sys.exc_info()[2])
  File "/home/user/anaconda3/lib/python3.12/site-packages/wandb/apis/normalize.py", line 25, in wrapper
    return func(*args, **kwargs)
           ^^^^^^^^^^^^^^^^^^^^^
  File "/home/user/anaconda3/lib/python3.12/site-packages/wandb/sdk/internal/internal_api.py", line 1139, in sweep
    raise ValueError(f"Sweep {entity}/{project}/{sweep} not found")
wandb.errors.errors.CommError: Sweep da24s019-indian-institute-of-technology-madras/CNN_Assignment/0qfnbfu7 not found

2025-04-10 18:57:29 ERROR Traceback (most recent call last):
  File "/home/user/anaconda3/lib/python3.12/site-packages/wandb/apis/normalize.py", line 25, in wrapper
    return func(*args, **kwargs)
           ^^^^^^^^^^^^^^^^^^^^^
  File "/home/user/anaconda3/lib/python3.12/site-packages/wandb/sdk/internal/internal_api.py", line 1139, in sweep
    raise ValueError(f"Sweep {entity}/{project}/{sweep} not found")
ValueError: Sweep da24s019-indian-institute-of-technology-madras/CNN_Assignment/gd5xyth0 not found

During handling of the above exception, another exception occurred:

Traceback (most recent call last):
  File "/home/user/anaconda3/lib/python3.12/site-packages/wandb/cli/cli.py", line 104, in wrapper
    return func(*args, **kwargs)
           ^^^^^^^^^^^^^^^^^^^^^
  File "/home/user/anaconda3/lib/python3.12/site-packages/wandb/cli/cli.py", line 1676, in agent
    wandb_agent.agent(sweep_id, entity=entity, project=project, count=count)
  File "/home/user/anaconda3/lib/python3.12/site-packages/wandb/wandb_agent.py", line 567, in agent
    return run_agent(
           ^^^^^^^^^^
  File "/home/user/anaconda3/lib/python3.12/site-packages/wandb/wandb_agent.py", line 526, in run_agent
    agent.run()
  File "/home/user/anaconda3/lib/python3.12/site-packages/wandb/wandb_agent.py", line 193, in run
    sweep_obj = self._api.sweep(self._sweep_id, "{}")
                ^^^^^^^^^^^^^^^^^^^^^^^^^^^^^^^^^^^^^
  File "/home/user/anaconda3/lib/python3.12/site-packages/wandb/apis/internal.py", line 134, in sweep
    return self.api.sweep(*args, **kwargs)
           ^^^^^^^^^^^^^^^^^^^^^^^^^^^^^^^
  File "/home/user/anaconda3/lib/python3.12/site-packages/wandb/apis/normalize.py", line 79, in wrapper
    raise CommError(message, err).with_traceback(sys.exc_info()[2])
  File "/home/user/anaconda3/lib/python3.12/site-packages/wandb/apis/normalize.py", line 25, in wrapper
    return func(*args, **kwargs)
           ^^^^^^^^^^^^^^^^^^^^^
  File "/home/user/anaconda3/lib/python3.12/site-packages/wandb/sdk/internal/internal_api.py", line 1139, in sweep
    raise ValueError(f"Sweep {entity}/{project}/{sweep} not found")
wandb.errors.errors.CommError: Sweep da24s019-indian-institute-of-technology-madras/CNN_Assignment/gd5xyth0 not found

2025-04-10 20:08:29 ERROR Traceback (most recent call last):
  File "/home/user/anaconda3/lib/python3.12/site-packages/wandb/apis/normalize.py", line 25, in wrapper
    return func(*args, **kwargs)
           ^^^^^^^^^^^^^^^^^^^^^
  File "/home/user/anaconda3/lib/python3.12/site-packages/wandb/sdk/internal/internal_api.py", line 1139, in sweep
    raise ValueError(f"Sweep {entity}/{project}/{sweep} not found")
ValueError: Sweep da24s019-indian-institute-of-technology-madras/inat-cnn-sweep/7goys794 not found

During handling of the above exception, another exception occurred:

Traceback (most recent call last):
  File "/home/user/anaconda3/lib/python3.12/site-packages/wandb/cli/cli.py", line 104, in wrapper
    return func(*args, **kwargs)
           ^^^^^^^^^^^^^^^^^^^^^
  File "/home/user/anaconda3/lib/python3.12/site-packages/wandb/cli/cli.py", line 1676, in agent
    wandb_agent.agent(sweep_id, entity=entity, project=project, count=count)
  File "/home/user/anaconda3/lib/python3.12/site-packages/wandb/wandb_agent.py", line 567, in agent
    return run_agent(
           ^^^^^^^^^^
  File "/home/user/anaconda3/lib/python3.12/site-packages/wandb/wandb_agent.py", line 526, in run_agent
    agent.run()
  File "/home/user/anaconda3/lib/python3.12/site-packages/wandb/wandb_agent.py", line 193, in run
    sweep_obj = self._api.sweep(self._sweep_id, "{}")
                ^^^^^^^^^^^^^^^^^^^^^^^^^^^^^^^^^^^^^
  File "/home/user/anaconda3/lib/python3.12/site-packages/wandb/apis/internal.py", line 134, in sweep
    return self.api.sweep(*args, **kwargs)
           ^^^^^^^^^^^^^^^^^^^^^^^^^^^^^^^
  File "/home/user/anaconda3/lib/python3.12/site-packages/wandb/apis/normalize.py", line 79, in wrapper
    raise CommError(message, err).with_traceback(sys.exc_info()[2])
  File "/home/user/anaconda3/lib/python3.12/site-packages/wandb/apis/normalize.py", line 25, in wrapper
    return func(*args, **kwargs)
           ^^^^^^^^^^^^^^^^^^^^^
  File "/home/user/anaconda3/lib/python3.12/site-packages/wandb/sdk/internal/internal_api.py", line 1139, in sweep
    raise ValueError(f"Sweep {entity}/{project}/{sweep} not found")
wandb.errors.errors.CommError: Sweep da24s019-indian-institute-of-technology-madras/inat-cnn-sweep/7goys794 not found

