Traceback (most recent call last):
  File "/home/user/anaconda3/lib/python3.12/site-packages/wandb/sdk/wandb_config.py", line 165, in __getattr__
    return self.__getitem__(key)
           ^^^^^^^^^^^^^^^^^^^^^
  File "/home/user/anaconda3/lib/python3.12/site-packages/wandb/sdk/wandb_config.py", line 130, in __getitem__
    return self._items[key]
           ~~~~~~~~~~~^^^^^
KeyError: 'activation'

The above exception was the direct cause of the following exception:

Traceback (most recent call last):
  File "/tmp/ipykernel_191692/2172409216.py", line 5, in sweep_train
    model = FlexibleCNN(config)
            ^^^^^^^^^^^^^^^^^^^
  File "/home/user/Documents/Books/DA24S019_Assignment_2/Part_A/model.py", line 19, in __init__
    activation = activation_map[config.activation]
                                ^^^^^^^^^^^^^^^^^
  File "/home/user/anaconda3/lib/python3.12/site-packages/wandb/sdk/wandb_config.py", line 167, in __getattr__
    raise AttributeError(
AttributeError: <class 'wandb.sdk.wandb_config.Config'> object has no attribute 'activation'
